<?xml version="1.0"?>
<robot xmlns:xacro="http://www.ros.org/wiki/xacro" name="rover">
  
  <!-- Properties -->
  <xacro:property name="show_lidar" value="false"/>
  <xacro:property name="base_width" value="0.4"/>
  <xacro:property name="base_length" value="0.6"/>
  <xacro:property name="base_height" value="0.2"/>
  <xacro:property name="wheel_radius" value="0.1"/>
  <xacro:property name="wheel_width" value="0.05"/>
  <xacro:property name="wheel_separation" value="0.45"/>
  
  <!-- Base Link -->
  <link name="base_link">
    <visual>
      <geometry>
        <box size="${base_length} ${base_width} ${base_height}"/>
      </geometry>
      <material name="blue">
        <color rgba="0.2 0.2 0.8 1.0"/>
      </material>
    </visual>
    <collision>
      <geometry>
        <box size="${base_length} ${base_width} ${base_height}"/>
      </geometry>
    </collision>
    <inertial>
      <mass value="10.0"/>
      <inertia ixx="0.133" ixy="0.0" ixz="0.0" iyy="0.333" iyz="0.0" izz="0.433"/>
    </inertial>
  </link>
  <!-- Footprint link for navigation -->
  <link name="base_footprint"/>
  
  <joint name="base_footprint_joint" type="fixed">
    <parent link="base_footprint"/>
    <child link="base_link"/>
    <origin xyz="0 0 ${wheel_radius}" rpy="0 0 0"/>
  </joint>
  <!-- Wheel Macro -->
  <xacro:macro name="wheel" params="prefix reflect">
    <link name="${prefix}_wheel">
      <visual>
        <geometry>
          <cylinder radius="${wheel_radius}" length="${wheel_width}"/>
        </geometry>
        <origin xyz="0 0 0" rpy="${pi/2} 0 0"/>
        <material name="black">
          <color rgba="0.1 0.1 0.1 1.0"/>
        </material>
      </visual>
      <collision>
        <geometry>
          <cylinder radius="${wheel_radius}" length="${wheel_width}"/>
        </geometry>
        <origin xyz="0 0 0" rpy="${pi/2} 0 0"/>
      </collision>
      <inertial>
        <mass value="1.0"/>
        <inertia ixx="0.00208" ixy="0.0" ixz="0.0" iyy="0.00208" iyz="0.0" izz="0.00375"/>
      </inertial>
    </link>
    <joint name="${prefix}_wheel_joint" type="continuous">
      <parent link="base_link"/>
      <child link="${prefix}_wheel"/>
      <origin xyz="0 ${reflect * wheel_separation/2} ${-base_height/2}" rpy="0 0 0"/>
      <axis xyz="0 1 0"/>
    </joint>
  </xacro:macro>
  <!-- Create wheels -->
  <xacro:wheel prefix="left" reflect="1"/>
  <xacro:wheel prefix="right" reflect="-1"/>
  <!-- Caster wheel front -->
  <link name="caster_front">
    <visual>
      <geometry>
        <sphere radius="${wheel_radius/2}"/>
      </geometry>
      <material name="gray">
        <color rgba="0.5 0.5 0.5 1.0"/>
      </material>
    </visual>
    <collision>
      <geometry>
        <sphere radius="${wheel_radius/2}"/>
      </geometry>
      <surface>
        <friction>
          <ode>
            <mu>0</mu>
            <mu2>0</mu2>
          </ode>
        </friction>
      </surface>
    </collision>
    <inertial>
      <mass value="0.1"/>
      <inertia ixx="0.0001" ixy="0.0" ixz="0.0" iyy="0.0001" iyz="0.0" izz="0.0001"/>
    </inertial>
  </link>
  <joint name="caster_front_joint" type="fixed">
    <parent link="base_link"/>
    <child link="caster_front"/>
    <origin xyz="${base_length/2 - wheel_radius/2} 0 ${-base_height/2 - wheel_radius/2}" rpy="0 0 0"/>
  </joint>
  <!-- Caster wheel back -->
  <link name="caster_back">
    <visual>
      <geometry>
        <sphere radius="${wheel_radius/2}"/>
      </geometry>
      <material name="gray">
        <color rgba="0.5 0.5 0.5 1.0"/>
      </material>
    </visual>
    <collision>
      <geometry>
        <sphere radius="${wheel_radius/2}"/>
      </geometry>
      <surface>
        <friction>
          <ode>
            <mu>0</mu>
            <mu2>0</mu2>
          </ode>
        </friction>
      </surface>
    </collision>
    <inertial>
      <mass value="0.1"/>
      <inertia ixx="0.0001" ixy="0.0" ixz="0.0" iyy="0.0001" iyz="0.0" izz="0.0001"/>
    </inertial>
  </link>
  <joint name="caster_back_joint" type="fixed">
    <parent link="base_link"/>
    <child link="caster_back"/>
    <origin xyz="${-base_length/2 + wheel_radius/2} 0 ${-base_height/2 - wheel_radius/2}" rpy="0 0 0"/>
  </joint>
  <!-- 3D LiDAR Sensor (Velodyne-style) -->
  <link name="lidar_link">
    <visual>
      <geometry>
        <cylinder radius="0.05" length="0.07"/>
      </geometry>
      <material name="black">
        <color rgba="0.1 0.1 0.1 1.0"/>
      </material>
    </visual>
    <collision>
      <geometry>
        <cylinder radius="0.05" length="0.07"/>
      </geometry>
    </collision>
    <inertial>
      <mass value="0.2"/>
      <inertia ixx="0.0001" ixy="0.0" ixz="0.0" iyy="0.0001" iyz="0.0" izz="0.0001"/>
    </inertial>
  </link>
  <joint name="lidar_joint" type="fixed">
    <parent link="base_link"/>
    <child link="lidar_link"/>
    <origin xyz="0.2 0 ${base_height/2 + 0.15}" rpy="0 0 0"/>
  </joint>
  <!-- ✅ FIXED: ZED camera frame now attached to base_link (rotates with robot) -->
  <link name="zed_left_camera_frame"/>
  <joint name="zed_camera_joint" type="fixed">
    <parent link="base_link"/>
    <child link="zed_left_camera_frame"/>
    <origin xyz="0.2 0 ${base_height/2 + 0.15}" rpy="0 0 0"/>
  </joint>
  <!-- Gazebo 3D LiDAR Plugin (GPU accelerated) -->
  <gazebo reference="lidar_link">
    <sensor type="gpu_ray" name="velodyne_sensor">
      <pose>0 0 0 0 0 0</pose>
      <visualize>${show_lidar}</visualize>
      <update_rate>10</update_rate>
      <ray>
        <scan>
          <horizontal>
            <samples>360</samples>
            <resolution>1</resolution>
            <min_angle>-${11*pi/36}</min_angle>
            <max_angle>${11*pi/36}</max_angle>
          </horizontal>
          <vertical>
            <samples>16</samples>
            <resolution>1</resolution>
            <min_angle>-0.6</min_angle>
            <max_angle>0.3</max_angle>
          </vertical>
        </scan>
        <range>
          <min>0.3</min>
          <max>50.0</max>
          <max>50.0</max>
          <resolution>0.01</resolution>
        </range>
        <noise>
          <type>gaussian</type>
          <mean>0.0</mean>
          <stddev>0.01</stddev>
        </noise>
      </ray>
      <plugin name="gazebo_ros_velodyne" filename="libgazebo_ros_velodyne_laser.so">
        <topicName>velodyne_points</topicName>
        <frameName>lidar_link</frameName>
        <organize_cloud>false</organize_cloud>
        <min_range>0.3</min_range>
        <max_range>50.0</max_range>
      </plugin>
    </sensor>
  </gazebo>
  <!-- Differential Drive Plugin -->
  <gazebo>
    <plugin name="differential_drive_controller" filename="libgazebo_ros_diff_drive.so">
      <update_rate>50</update_rate>
      <left_joint>left_wheel_joint</left_joint>
      <right_joint>right_wheel_joint</right_joint>
      <wheel_separation>${wheel_separation}</wheel_separation>
      <wheel_diameter>${2*wheel_radius}</wheel_diameter>
      <max_wheel_torque>20</max_wheel_torque>
      <max_wheel_acceleration>1.0</max_wheel_acceleration>
      <command_topic>cmd_vel</command_topic>
      <publish_odom>true</publish_odom>
      <publish_odom_tf>true</publish_odom_tf>
      <publish_wheel_tf>false</publish_wheel_tf>
      <odometry_topic>odom</odometry_topic>
      <odometry_frame>odom</odometry_frame>
      <robot_base_frame>base_footprint</robot_base_frame>
    </plugin>
  </gazebo>
  <!-- Gazebo material colors -->
  <gazebo reference="base_link">
    <material>Gazebo/Blue</material>
  </gazebo>
  
  <!-- Drive wheels with good traction -->
  <gazebo reference="left_wheel">
    <mu1>1.0</mu1>
    <mu2>1.0</mu2>
    <kp>1000000.0</kp>
    <kd>100.0</kd>
    <minDepth>0.001</minDepth>
    <material>Gazebo/Black</material>
  </gazebo>
  
  <gazebo reference="right_wheel">
    <mu1>1.0</mu1>
    <mu2>1.0</mu2>
    <kp>1000000.0</kp>
    <kd>100.0</kd>
    <minDepth>0.001</minDepth>
    <material>Gazebo/Black</material>
  </gazebo>
  
  <gazebo reference="lidar_link">
    <material>Gazebo/Black</material>
  </gazebo>
  
  <!-- Frictionless casters -->
  <gazebo reference="caster_front">
    <mu1>0.0</mu1>
    <mu2>0.0</mu2>
    <kp>1000000.0</kp>
    <kd>100.0</kd>
    <material>Gazebo/Grey</material>
  </gazebo>
  
  <gazebo reference="caster_back">
    <mu1>0.0</mu1>
    <mu2>0.0</mu2>
    <kp>1000000.0</kp>
    <kd>100.0</kd>
    <material>Gazebo/Grey</material>
  </gazebo>
</robot>
